<?xml version="1.0" ?>
<!-- =================================================================================== -->
<!-- |    This document was autogenerated by xacro from sw_top_level_amiga.urdf.xacro  | -->
<!-- |    EDITING THIS FILE BY HAND IS NOT RECOMMENDED                                 | -->
<!-- =================================================================================== -->
<!-- This URDF was automatically created by SolidWorks to URDF Exporter! Originally created by Stephen Brawner (brawner@gmail.com) 
     Commit Version: 1.6.0-4-g7f85cfe  Build Version: 1.6.7995.38578
     For more information, please see http://wiki.ros.org/sw_urdf_exporter -->
<robot name="top_level_amiga">
  <!-- <mesh filename="file://$(find diff_drive_bot)/meshes/body.stl" /> -->
  <!-- filename="package://nursery_test2/meshes/base_link.STL" -->
  <link name="base_link">
    <inertial>
      <origin rpy="0 0 0" xyz="0 0 0.44372"/>
      <mass value="236.09"/>
      <inertia ixx="3.6918" ixy="-0.007109" ixz="-3.74E-05" iyy="3.6753" iyz="1.5188E-05" izz="3.1829"/>
    </inertial>
    <visual>
      <origin rpy="0 0 0" xyz="0 0 0"/>
      <geometry>
        <mesh filename="file:///home/atharvgoel/LEAPv1/install/nursery_test2/share/nursery_test2/meshes/base_link.STL"/>
      </geometry>
      <material name="">
        <color rgba="0.118 0.506 0.729 1"/>
      </material>
    </visual>
    <collision>
      <origin rpy="0 0 0" xyz="0 0 0"/>
      <geometry>
        <mesh filename="file:///home/atharvgoel/LEAPv1/install/nursery_test2/share/nursery_test2/meshes/base_link_collision.STL"/>
      </geometry>
    </collision>
  </link>
  <!-- base_footprint is used with Nav2 -->
  <link name="base_footprint"/>
  <joint name="dummy_joint" type="fixed">
    <parent link="base_link"/>
    <child link="base_footprint"/>
  </joint>
  <link name="FL_wheel">
    <inertial>
      <origin rpy="0 0 0" xyz="4.3098E-07 5.5068E-07 -0.00020749"/>
      <mass value="15.628"/>
      <inertia ixx="0.153" ixy="1.1085E-06" ixz="2.7485E-07" iyy="0.153" iyz="2.341E-07" izz="0.28441"/>
    </inertial>
    <visual>
      <origin rpy="0 0 0" xyz="0 0 0"/>
      <geometry>
        <mesh filename="file:///home/atharvgoel/LEAPv1/install/nursery_test2/share/nursery_test2/meshes/wheel.STL"/>
      </geometry>
      <material name="">
        <color rgba="0 0 0 1"/>
      </material>
    </visual>
    <collision>
      <origin rpy="0 0 0" xyz="0 0 0"/>
      <geometry>
        <mesh filename="file:///home/atharvgoel/LEAPv1/install/nursery_test2/share/nursery_test2/meshes/wheel_collision.STL"/>
      </geometry>
      <surface>
        <friction>
          <ode>
            <mu>1</mu>
            <mu2>1</mu2>
            <slip1>0</slip1>
            <slip2>0</slip2>
          </ode>
        </friction>
      </surface>
    </collision>
  </link>
  <joint name="FL_wheel_j" type="continuous">
    <origin rpy="1.5708 0 3.1416" xyz="0.2658 0.32928 0.2159"/>
    <parent link="base_link"/>
    <child link="FL_wheel"/>
    <axis xyz="0 0 1"/>
  </joint>
  <link name="FR_wheel">
    <inertial>
      <origin rpy="0 0 0" xyz="4.3153E-07 5.4433E-07 -0.00020748"/>
      <mass value="15.628"/>
      <inertia ixx="0.153" ixy="1.1081E-06" ixz="2.8146E-07" iyy="0.153" iyz="2.3106E-07" izz="0.28441"/>
    </inertial>
    <visual>
      <origin rpy="0 0 0" xyz="0 0 0"/>
      <geometry>
        <mesh filename="file:///home/atharvgoel/LEAPv1/install/nursery_test2/share/nursery_test2/meshes/wheel.STL"/>
      </geometry>
      <material name="">
        <color rgba="0 0 0 1"/>
      </material>
    </visual>
    <collision>
      <origin rpy="0 0 0" xyz="0 0 0"/>
      <geometry>
        <mesh filename="file:///home/atharvgoel/LEAPv1/install/nursery_test2/share/nursery_test2/meshes/wheel_collision.STL"/>
      </geometry>
      <surface>
        <friction>
          <ode>
            <mu>1</mu>
            <mu2>1</mu2>
            <slip1>0</slip1>
            <slip2>0</slip2>
          </ode>
        </friction>
      </surface>
    </collision>
  </link>
  <joint name="FR_wheel_j" type="continuous">
    <origin rpy="1.5708 0 3.1416" xyz="0.26669 -0.32928 0.2159"/>
    <parent link="base_link"/>
    <child link="FR_wheel"/>
    <axis xyz="0 0 1"/>
  </joint>
  <link name="RL_wheel">
    <inertial>
      <origin rpy="0 0 0" xyz="4.2324E-07 5.6831E-07 -0.00020749"/>
      <mass value="15.628"/>
      <inertia ixx="0.153" ixy="1.0985E-06" ixz="2.7036E-07" iyy="0.153" iyz="2.4709E-07" izz="0.28441"/>
    </inertial>
    <visual>
      <origin rpy="0 0 0" xyz="0 0 0"/>
      <geometry>
        <mesh filename="file:///home/atharvgoel/LEAPv1/install/nursery_test2/share/nursery_test2/meshes/wheel.STL"/>
      </geometry>
      <material name="">
        <color rgba="0 0 0 1"/>
      </material>
    </visual>
    <collision>
      <origin rpy="0 0 0" xyz="0 0 0"/>
      <geometry>
        <mesh filename="file:///home/atharvgoel/LEAPv1/install/nursery_test2/share/nursery_test2/meshes/wheel_collision.STL"/>
      </geometry>
      <surface>
        <friction>
          <ode>
            <mu>1</mu>
            <mu2>1</mu2>
            <slip1>0</slip1>
            <slip2>0</slip2>
          </ode>
        </friction>
      </surface>
    </collision>
  </link>
  <joint name="RL_wheel_j" type="continuous">
    <origin rpy="1.5708 0 3.1416" xyz="-0.26671 0.32928 0.2159"/>
    <parent link="base_link"/>
    <child link="RL_wheel"/>
    <axis xyz="0 0 1"/>
  </joint>
  <link name="RR_wheel">
    <inertial>
      <origin rpy="0 0 0" xyz="4.3464E-07 5.6185E-07 -0.00020748"/>
      <mass value="15.628"/>
      <inertia ixx="0.153" ixy="1.11E-06" ixz="2.6707E-07" iyy="0.153" iyz="2.4203E-07" izz="0.28441"/>
    </inertial>
    <visual>
      <origin rpy="0 0 0" xyz="0 0 0"/>
      <geometry>
        <mesh filename="file:///home/atharvgoel/LEAPv1/install/nursery_test2/share/nursery_test2/meshes/wheel.STL"/>
      </geometry>
      <material name="">
        <color rgba="0 0 0 1"/>
      </material>
    </visual>
    <collision>
      <origin rpy="0 0 0" xyz="0 0 0"/>
      <geometry>
        <mesh filename="file:///home/atharvgoel/LEAPv1/install/nursery_test2/share/nursery_test2/meshes/wheel_collision.STL"/>
      </geometry>
      <surface>
        <friction>
          <ode>
            <mu>1</mu>
            <mu2>1</mu2>
            <slip1>0</slip1>
            <slip2>0</slip2>
          </ode>
        </friction>
      </surface>
    </collision>
  </link>
  <joint name="RR_wheel_j" type="continuous">
    <origin rpy="1.5708 0 3.1416" xyz="-0.26671 -0.32928 0.2159"/>
    <parent link="base_link"/>
    <child link="RR_wheel"/>
    <axis xyz="0 0 1"/>
  </joint>
  <link name="front_camera_hinge">
    <inertial>
      <origin rpy="0 0 0" xyz="0.072808 -0.032484 -0.00017047"/>
      <mass value="0.21875"/>
      <inertia ixx="0.00029961" ixy="4.6954E-06" ixz="-3.6958E-07" iyy="0.00033063" iyz="2.5824E-07" izz="7.9946E-05"/>
    </inertial>
    <visual>
      <origin rpy="0 0 0" xyz="0 0 0"/>
      <geometry>
        <mesh filename="file:///home/atharvgoel/LEAPv1/install/nursery_test2/share/nursery_test2/meshes/camera.STL"/>
      </geometry>
      <material name="">
        <color rgba="1 0 0 1"/>
      </material>
    </visual>
  </link>
  <joint name="front_camera_hinge_j" type="fixed">
    <origin rpy="1.5708 -0.523599 0" xyz="0.4391 0.01207 0.95531"/>
    <!-- change pitch to adjust camera angle. + is down-->
    <parent link="base_link"/>
    <child link="front_camera_hinge"/>
  </joint>
  <link name="front_camera">
  </link>
  <joint name="front_camera_j" type="fixed">
    <origin rpy="-1.5708 0 -0.82903" xyz="0.10238 -0.078277 0.0001016"/>
    <!--0.82903 applied in ypr order-->
    <parent link="front_camera_hinge"/>
    <child link="front_camera"/>
    <axis xyz="0 0 0"/>
  </joint>
  <link name="front_camera_optical">
  </link>
  <joint name="front_camera_optical_j" type="fixed">
    <origin rpy="-1.5708 0 -1.5708" xyz="0 0 0"/>
    <!--0.82903 applied in ypr order-->
    <parent link="front_camera"/>
    <child link="front_camera_optical"/>
    <axis xyz="0 0 0"/>
  </joint>
  <link name="lidar_hinge">
    <inertial>
      <origin rpy="0 0 0" xyz="0.12957 -0.043305 -0.00024862"/>
      <mass value="1.5307"/>
      <inertia ixx="0.0017351" ixy="0.0010109" ixz="-1.665E-06" iyy="0.002688" iyz="8.5186E-07" izz="0.0029184"/>
    </inertial>
    <visual>
      <origin rpy="0 0 0" xyz="0 0 0"/>
      <geometry>
        <mesh filename="file:///home/atharvgoel/LEAPv1/install/nursery_test2/share/nursery_test2/meshes/lidar.STL"/>
      </geometry>
      <material name="">
        <color rgba="0 1 0 1"/>
      </material>
    </visual>
  </link>
  <joint name="lidar_hinge_j" type="fixed">
    <origin rpy="1.5708 -0.4363 0" xyz="0.4391 0.01207 1.1077"/>
    <!-- change pitch to adjust camera angle. + is down.  -0.4363 makes it parallel to ground-->
    <parent link="base_link"/>
    <child link="lidar_hinge"/>
  </joint>
  <link name="lidar">
  </link>
  <joint name="lidar_j" type="fixed">
    <origin rpy="-1.5708 0 -0.43633" xyz="0.14354 -0.042185 0"/>
    <!--0.82903 applied in ypr order-->
    <parent link="lidar_hinge"/>
    <child link="lidar"/>
    <axis xyz="0 0 0"/>
  </joint>
  <link name="GNSS">
    <inertial>
      <origin rpy="0 0 0" xyz="-0.046445 0 0.013514"/>
      <mass value="0.79165"/>
      <inertia ixx="0.00073881" ixy="-1.239E-06" ixz="1.3737E-05" iyy="0.00065902" iyz="0" izz="0.0011813"/>
    </inertial>
    <visual>
      <origin rpy="0 0 0" xyz="0 0 0"/>
      <geometry>
        <mesh filename="file:///home/atharvgoel/LEAPv1/install/nursery_test2/share/nursery_test2/meshes/GNSS.STL"/>
      </geometry>
      <material name="">
        <color rgba="0 1 0 1"/>
      </material>
    </visual>
  </link>
  <joint name="GNSS_j" type="fixed">
    <origin rpy="0 0 0" xyz="-0.22005 0 1.5086"/>
    <!-- change pitch to adjust camera angle. + is down.  -0.4363 makes it parallel to ground-->
    <parent link="base_link"/>
    <child link="GNSS"/>
  </joint>
  <gazebo reference="front_camera">
    <sensor name="camera" type="camera">
      <camera>
        <camera_info_topic>camera/camera_info</camera_info_topic>
        <horizontal_fov>1.047</horizontal_fov>
        <image>
          <width>320</width>
          <height>240</height>
        </image>
        <clip>
          <near>0.1</near>
          <far>100</far>
        </clip>
      </camera>
      <always_on>1</always_on>
      <update_rate>10</update_rate>
      <visualize>true</visualize>
      <topic>camera/image_raw</topic>
      <gz_frame_id>front_camera_optical</gz_frame_id>
    </sensor>
  </gazebo>
  <gazebo reference="lidar">
    <sensor name="gpu_lidar" type="gpu_lidar">
      <!--block_laser_sensor might work for 3d?-->
      <!-- <pose relative_to='lidar_frame'>0 0 0 0 0 0</pose> -->
      <pose>0 0 0 0 0 0</pose>
      <topic>scan</topic>
      <update_rate>10</update_rate>
      <ray>
        <scan>
          <horizontal>
            <samples>640</samples>
            <resolution>1</resolution>
            <min_angle>-1.396263</min_angle>
            <max_angle>1.396263</max_angle>
          </horizontal>
          <vertical>
            <!-- <samples>1</samples>
                    <resolution>0.01</resolution>
                    <min_angle>0</min_angle>
                    <max_angle>0</max_angle> -->
            <samples>15</samples>
            <resolution>1</resolution>
            <min_angle>-0.2618</min_angle>
            <max_angle>0.2618</max_angle>
          </vertical>
        </scan>
        <range>
          <min>0.08</min>
          <max>10.0</max>
          <resolution>0.01</resolution>
        </range>
      </ray>
      <always_on>1</always_on>
      <visualize>true</visualize>
      <gz_frame_id>lidar</gz_frame_id>
    </sensor>
  </gazebo>
  <!-- addition of IMU sensor -->
  <gazebo reference="GNSS">
    <sensor name="imu_sensor" type="imu">
      <always_on>1</always_on>
      <update_rate>10</update_rate>
      <visualize>true</visualize>
      <topic>imu</topic>
      <gz_frame_id>GNSS</gz_frame_id>
      <!-- Set the covariance matrix.  Need to make sure reference frame is right here -->
      <!-- The noise values are added to the "true" values. better way may be to rebroadcast it with the covariance info appended -->
      <!-- <imu>
        <angular_velocity>
          <x>
            <noise type="gaussian">
                <mean>0.0</mean>
                <stddev>0.0001</stddev>
                <bias_mean>0.0</bias_mean>
                <bias_stddev>0.0</bias_stddev>
            </noise>
          </x>
          <y>
          <noise type="gaussian">
            <mean>0.0</mean>
            <stddev>0.0001</stddev>
            <bias_mean>0.0</bias_mean>
            <bias_stddev>0.0</bias_stddev>
          </noise>
          </y>
          <z>
            <noise type="gaussian">
              <mean>0.0</mean>
              <stddev>0.0001</stddev>
              <bias_mean>0.0</bias_mean>
              <bias_stddev>0.0</bias_stddev>
            </noise>
          </z>
        </angular_velocity>
        <linear_acceleration>
          <x>
            <noise type="gaussian">
              <mean>0.0</mean>
              <stddev>0.0001</stddev>
              <bias_mean>0.0</bias_mean>
              <bias_stddev>0.0</bias_stddev>
            </noise>
          </x>
          <y>
            <noise type="gaussian">
              <mean>0.0</mean>
              <stddev>0.0001</stddev>
              <bias_mean>0.0</bias_mean>
              <bias_stddev>0.0</bias_stddev>
            </noise>
          </y>
          <z>
            <noise type="gaussian">
              <mean>0.0</mean>
              <stddev>0.0001</stddev>
              <bias_mean>0.0</bias_mean>
              <bias_stddev>0.0</bias_stddev>
            </noise>
          </z>
        </linear_acceleration>
      </imu> -->
    </sensor>
  </gazebo>
  <!-- addition of GPS sensor.  Requires adding spherical coordinate to world
per: https://robotics.stackexchange.com/questions/29352/gps-sensor-plugin-in-ignition -->
  <gazebo reference="GNSS">
    <sensor name="navsat" type="navsat">
      <always_on>1</always_on>
      <update_rate>1</update_rate>
      <visualize>true</visualize>
      <topic>navsat</topic>
      <gz_frame_id>GNSS</gz_frame_id>
    </sensor>
  </gazebo>
  <ros2_control name="IgnitionSystemTest" type="system">
    <hardware>
      <plugin>gz_ros2_control/GazeboSimSystem</plugin>
    </hardware>
    <joint name="FL_wheel_j">
      <command_interface name="velocity">
        <!-- m/s -->
        <!-- <param name = "min">-2.54</param>  
        <param name = "max">2.54</param>  -->
      </command_interface>
      <state_interface name="velocity"/>
      <state_interface name="position"/>
      <state_interface name="effort"/>
    </joint>
    <joint name="FR_wheel_j">
      <command_interface name="velocity">
        <!-- m/s -->
        <!-- <param name = "min">-2.54</param>  
        <param name = "max">2.54</param>  -->
      </command_interface>
      <state_interface name="velocity"/>
      <state_interface name="position"/>
      <!-- <state_interface name="effort"/> -->
    </joint>
    <joint name="RL_wheel_j">
      <command_interface name="velocity">
        <!-- m/s -->
        <!-- <param name = "min">-2.54</param> 
        <param name = "max">2.54</param>  -->
      </command_interface>
      <state_interface name="velocity"/>
      <state_interface name="position"/>
      <!-- <state_interface name="effort"/> -->
    </joint>
    <joint name="RR_wheel_j">
      <command_interface name="velocity">
        <!-- m/s -->
        <!-- <param name = "min">-2.54</param> 
        <param name = "max">2.54</param>  -->
      </command_interface>
      <state_interface name="velocity"/>
      <state_interface name="position"/>
      <!-- <state_interface name="effort"/> -->
    </joint>
  </ros2_control>
  <gazebo>
    <!-- <plugin filename="libgz_ros2_control-system.so" name="gz_ros2_control::GazeboSimROS2ControlPlugin"> -->
    <plugin filename="gz_ros2_control-system"name="gz_ros2_control::GazeboSimROS2ControlPlugin">
      <parameters>/home/atharvgoel/LEAPv1/install/nursery_test2/share/nursery_test2/config/diff_controller.yaml</parameters>
      <!-- <ros>
        <remapping>/tf:=/tf_diff_cont</remapping>
      </ros> -->
    </plugin>
  </gazebo>
</robot>
